#VRML_SIM R2019a utf8
WorldInfo {
}
Viewpoint {
  orientation 0.4299120715354241 -0.8768583508720128 -0.21516282962940975 5.2458921785980746
  position 1.9636991641093273 2.616640800957245 1.570800815173307
}
TexturedBackground {
}
TexturedBackgroundLight {
}
Floor {
}
DEF BOX_COVER Solid {
  translation 0 0.02500000000000522 0
  children [
    Group {
      children [
        Shape {
          appearance DEF CBOX_COVER PBRAppearance {
          }
          geometry DEF GBOX_COVER Box {
            size 1 0.05 1
          }
        }
        Transform {
          translation 0 0.95 0
          children [
            Shape {
              appearance USE CBOX_COVER
              geometry USE GBOX_COVER
            }
          ]
        }
      ]
    }
  ]
}
DEF BOX_EDGE1 Solid {
  translation 0 0.1 0.495
  rotation 0 0 1 0
  children [
    Group {
      children [
        DEF BOX_FRAME1 Shape {
          appearance DEF CBOX_FRAME PBRAppearance {
            baseColor 0.8 0 0
          }
          geometry DEF G_BOX_FRAME Box {
            size 1 0.1 0.01
          }
        }
        Transform {
          translation 0 0.8 0
          rotation 0 0 1 0
          children [
            Shape {
              appearance USE CBOX_FRAME
              geometry USE G_BOX_FRAME
            }
          ]
        }
      ]
    }
    Group {
      children [
        Solid {
          translation 0.45 0.4 0
          rotation 0 0 1 1.57
          children [
            Shape {
              appearance USE CBOX_FRAME
              geometry DEF G_BOX_Frame1 Box {
                size 0.7 0.1 0.01
              }
            }
            Transform {
              translation 0 0.9 0
              children [
                Shape {
                  appearance USE CBOX_FRAME
                  geometry USE G_BOX_Frame1
                }
              ]
            }
          ]
        }
      ]
    }
    Group {
      children [
        Solid {
          translation 0 0.4 0
          rotation 0 0 1 0.71
          children [
            Shape {
              appearance USE CBOX_FRAME
              geometry Box {
                size 1.2 0.07 0.01
              }
            }
            Transform {
              rotation 0 0 1 1.7
              children [
                Shape {
                  appearance USE CBOX_FRAME
                  geometry Box {
                    size 1.2 0.07 0.01
                  }
                }
              ]
            }
          ]
          name "solid(1)"
        }
      ]
    }
  ]
  name "solid(1)"
}
DEF BOX_EDGE2 Solid {
  translation 0 0.1 -0.495
  rotation 0 0 1 0
  children [
    Group {
      children [
        DEF BOX_FRAME1 Shape {
          appearance DEF CBOX_FRAME PBRAppearance {
            baseColor 0.8 0 0
          }
          geometry DEF G_BOX_FRAME Box {
            size 1 0.1 0.01
          }
        }
        Transform {
          translation 0 0.8 0
          rotation 0 0 1 0
          children [
            Shape {
              appearance USE CBOX_FRAME
              geometry USE G_BOX_FRAME
            }
          ]
        }
      ]
    }
    Group {
      children [
        Solid {
          translation 0.45 0.4 0
          rotation 0 0 1 1.57
          children [
            Shape {
              appearance USE CBOX_FRAME
              geometry DEF G_BOX_Frame1 Box {
                size 0.7 0.1 0.01
              }
            }
            Transform {
              translation 0 0.9 0
              children [
                Shape {
                  appearance USE CBOX_FRAME
                  geometry USE G_BOX_Frame1
                }
              ]
            }
          ]
        }
      ]
    }
    Group {
      children [
        Solid {
          translation 0 0.4 0
          rotation 0 0 1 0.71
          children [
            Shape {
              appearance USE CBOX_FRAME
              geometry Box {
                size 1.2 0.07 0.01
              }
            }
            Transform {
              rotation 0 0 1 1.7
              children [
                Shape {
                  appearance USE CBOX_FRAME
                  geometry Box {
                    size 1.2 0.07 0.01
                  }
                }
              ]
            }
          ]
          name "solid(1)"
        }
      ]
    }
  ]
  name "solid(2)"
}
DEF BOX_EDGE3 Solid {
  translation 0.495 0.1 0
  rotation 0 1 0 1.57
  children [
    Group {
      children [
        DEF BOX_FRAME1 Shape {
          appearance DEF CBOX_FRAME PBRAppearance {
            baseColor 0.8 0 0
          }
          geometry DEF G_BOX_FRAME Box {
            size 0.98 0.1 0.01
          }
        }
        Transform {
          translation 0 0.8 0
          rotation 0 0 1 0
          children [
            Shape {
              appearance USE CBOX_FRAME
              geometry USE G_BOX_FRAME
            }
          ]
        }
      ]
    }
    Group {
      children [
        Solid {
          translation 0.44 0.4 0
          rotation 0 0 1 1.57
          children [
            Shape {
              appearance USE CBOX_FRAME
              geometry DEF G_BOX_Frame1 Box {
                size 0.7 0.1 0.01
              }
            }
            Transform {
              translation 0 0.88 0
              children [
                Shape {
                  appearance USE CBOX_FRAME
                  geometry USE G_BOX_Frame1
                }
              ]
            }
          ]
        }
      ]
    }
    Group {
      children [
        Solid {
          translation 0 0.4 0
          rotation 0 0 1 0.71
          children [
            Shape {
              appearance USE CBOX_FRAME
              geometry Box {
                size 1.2 0.07 0.01
              }
            }
            Transform {
              rotation 0 0 1 1.7
              children [
                Shape {
                  appearance USE CBOX_FRAME
                  geometry Box {
                    size 1.2 0.07 0.01
                  }
                }
              ]
            }
          ]
          name "solid(1)"
        }
      ]
    }
  ]
  name "solid(3)"
}
DEF BOX_EDGE4 Solid {
  translation -0.495 0.1 0
  rotation 0 1 0 1.57
  children [
    Group {
      children [
        DEF BOX_FRAME1 Shape {
          appearance DEF CBOX_FRAME PBRAppearance {
            baseColor 0.8 0 0
          }
          geometry DEF G_BOX_FRAME Box {
            size 0.98 0.1 0.01
          }
        }
        Transform {
          translation 0 0.8 0
          rotation 0 0 1 0
          children [
            Shape {
              appearance USE CBOX_FRAME
              geometry USE G_BOX_FRAME
            }
          ]
        }
      ]
    }
    Group {
      children [
        Solid {
          translation 0.44 0.4 0
          rotation 0 0 1 1.57
          children [
            Shape {
              appearance USE CBOX_FRAME
              geometry DEF G_BOX_Frame1 Box {
                size 0.7 0.1 0.01
              }
            }
            Transform {
              translation 0 0.88 0
              children [
                Shape {
                  appearance USE CBOX_FRAME
                  geometry USE G_BOX_Frame1
                }
              ]
            }
          ]
        }
      ]
    }
    Group {
      children [
        Solid {
          translation 0 0.4 0
          rotation 0 0 1 0.71
          children [
            Shape {
              appearance USE CBOX_FRAME
              geometry Box {
                size 1.2 0.07 0.01
              }
            }
            Transform {
              rotation 0 0 1 1.7
              children [
                Shape {
                  appearance USE CBOX_FRAME
                  geometry Box {
                    size 1.2 0.07 0.01
                  }
                }
              ]
            }
          ]
          name "solid(1)"
        }
      ]
    }
  ]
  name "solid(4)"
}
DEF ELICE_FRAME Solid {
  translation 0 1.2 0
  children [
    Group {
      children [
        Shape {
          appearance DEF C_ELICE_FRAME PBRAppearance {
            baseColor 0.3058823529411765 0.6039215686274509 0.023529411764705882
            metalness 0
          }
          geometry DEF G_ELICE_CYL Cylinder {
            height 0.4
            radius 0.05
          }
        }
        HingeJoint {
          endPoint Solid {
            translation 0.08 0.25 0
            rotation 0 0 1 1.57
            children [
              Shape {
                appearance USE C_ELICE_FRAME
                geometry USE G_ELICE_CYL
              }
              HingeJoint {
                endPoint Solid {
                  translation 0 -0.205 0
                  rotation 0 1 0 0.78
                  children [
                    Shape {
                      appearance USE C_ELICE_FRAME
                      geometry Box {
                        size 0.5 0.01 0.1
                      }
                    }
                    HingeJoint {
                      endPoint Solid {
                        rotation 0 1 0 1.57
                        children [
                          Shape {
                            appearance USE C_ELICE_FRAME
                            geometry Box {
                              size 0.5 0.01 0.1
                            }
                          }
                        ]
                      }
                    }
                  ]
                }
              }
            ]
          }
        }
      ]
    }
  ]
  name "solid(5)"
  boundingObject USE G_ELICE_CYL
}
