#VRML_SIM R2019a utf8
WorldInfo {
}
Viewpoint {
  orientation 0.35223899819951027 -0.9306322797059342 -0.09925345392852275 5.695171014682685
  position 1.4221086251283186 1.5120407246122696 2.738191522107317
}
TexturedBackground {
}
TexturedBackgroundLight {
}
Floor {
}
DEF BOX_COVER Solid {
  translation 0 0.02500000000000522 0
  children [
    Group {
      children [
        Shape {
          appearance DEF CBOX_COVER PBRAppearance {
          }
          geometry DEF GBOX_COVER Box {
            size 1 0.05 1
          }
        }
        Transform {
          translation 0 0.95 0
          children [
            Shape {
              appearance USE CBOX_COVER
              geometry USE GBOX_COVER
            }
          ]
        }
      ]
    }
  ]
}
DEF BOX_EDGE1 Solid {
  translation 0 0.1 0.495
  rotation 0 0 1 0
  children [
    Group {
      children [
        DEF BOX_FRAME1 Shape {
          appearance DEF CBOX_FRAME PBRAppearance {
            baseColor 0.8 0 0
          }
          geometry DEF G_BOX_FRAME Box {
            size 1 0.1 0.01
          }
        }
        Transform {
          translation 0 0.8 0
          rotation 0 0 1 0
          children [
            Shape {
              appearance USE CBOX_FRAME
              geometry USE G_BOX_FRAME
            }
          ]
        }
      ]
    }
    Group {
      children [
        Solid {
          translation 0.45 0.4 0
          rotation 0 0 1 1.57
          children [
            Shape {
              appearance USE CBOX_FRAME
              geometry DEF G_BOX_Frame1 Box {
                size 0.7 0.1 0.01
              }
            }
            Transform {
              translation 0 0.9 0
              children [
                Shape {
                  appearance USE CBOX_FRAME
                  geometry USE G_BOX_Frame1
                }
              ]
            }
          ]
        }
      ]
    }
    Group {
      children [
        Solid {
          translation 0 0.4 0
          rotation 0 0 1 0.71
          children [
            Shape {
              appearance USE CBOX_FRAME
              geometry Box {
                size 1.2 0.07 0.01
              }
            }
            Transform {
              rotation 0 0 1 1.7
              children [
                Shape {
                  appearance USE CBOX_FRAME
                  geometry Box {
                    size 1.2 0.07 0.01
                  }
                }
              ]
            }
          ]
          name "solid(1)"
        }
      ]
    }
  ]
  name "solid(1)"
}
DEF BOX_EDGE2 Solid {
  translation 0 0.1 -0.495
  rotation 0 0 1 0
  children [
    Group {
      children [
        DEF BOX_FRAME1 Shape {
          appearance DEF CBOX_FRAME PBRAppearance {
            baseColor 0.8 0 0
          }
          geometry DEF G_BOX_FRAME Box {
            size 1 0.1 0.01
          }
        }
        Transform {
          translation 0 0.8 0
          rotation 0 0 1 0
          children [
            Shape {
              appearance USE CBOX_FRAME
              geometry USE G_BOX_FRAME
            }
          ]
        }
      ]
    }
    Group {
      children [
        Solid {
          translation 0.45 0.4 0
          rotation 0 0 1 1.57
          children [
            Shape {
              appearance USE CBOX_FRAME
              geometry DEF G_BOX_Frame1 Box {
                size 0.7 0.1 0.01
              }
            }
            Transform {
              translation 0 0.9 0
              children [
                Shape {
                  appearance USE CBOX_FRAME
                  geometry USE G_BOX_Frame1
                }
              ]
            }
          ]
        }
      ]
    }
    Group {
      children [
        Solid {
          translation 0 0.4 0
          rotation 0 0 1 0.71
          children [
            Shape {
              appearance USE CBOX_FRAME
              geometry Box {
                size 1.2 0.07 0.01
              }
            }
            Transform {
              rotation 0 0 1 1.7
              children [
                Shape {
                  appearance USE CBOX_FRAME
                  geometry Box {
                    size 1.2 0.07 0.01
                  }
                }
              ]
            }
          ]
          name "solid(1)"
        }
      ]
    }
  ]
  name "solid(2)"
}
DEF BOX_EDGE3 Solid {
  translation 0.495 0.1 0
  rotation 0 1 0 1.57
  children [
    Group {
      children [
        DEF BOX_FRAME1 Shape {
          appearance DEF CBOX_FRAME PBRAppearance {
            baseColor 0.8 0 0
          }
          geometry DEF G_BOX_FRAME Box {
            size 0.98 0.1 0.01
          }
        }
        Transform {
          translation 0 0.8 0
          rotation 0 0 1 0
          children [
            Shape {
              appearance USE CBOX_FRAME
              geometry USE G_BOX_FRAME
            }
          ]
        }
      ]
    }
    Group {
      children [
        Solid {
          translation 0.44 0.4 0
          rotation 0 0 1 1.57
          children [
            Shape {
              appearance USE CBOX_FRAME
              geometry DEF G_BOX_Frame1 Box {
                size 0.7 0.1 0.01
              }
            }
            Transform {
              translation 0 0.88 0
              children [
                Shape {
                  appearance USE CBOX_FRAME
                  geometry USE G_BOX_Frame1
                }
              ]
            }
          ]
        }
      ]
    }
    Group {
      children [
        Solid {
          translation 0 0.4 0
          rotation 0 0 1 0.71
          children [
            Shape {
              appearance USE CBOX_FRAME
              geometry Box {
                size 1.2 0.07 0.01
              }
            }
            Transform {
              rotation 0 0 1 1.7
              children [
                Shape {
                  appearance USE CBOX_FRAME
                  geometry Box {
                    size 1.2 0.07 0.01
                  }
                }
              ]
            }
          ]
          name "solid(1)"
        }
      ]
    }
  ]
  name "solid(3)"
}
DEF BOX_EDGE4 Solid {
  translation -0.495 0.1 0
  rotation 0 1 0 1.57
  children [
    Group {
      children [
        DEF BOX_FRAME1 Shape {
          appearance DEF CBOX_FRAME PBRAppearance {
            baseColor 0.8 0 0
          }
          geometry DEF G_BOX_FRAME Box {
            size 0.98 0.1 0.01
          }
        }
        Transform {
          translation 0 0.8 0
          rotation 0 0 1 0
          children [
            Shape {
              appearance USE CBOX_FRAME
              geometry USE G_BOX_FRAME
            }
          ]
        }
      ]
    }
    Group {
      children [
        Solid {
          translation 0.44 0.4 0
          rotation 0 0 1 1.57
          children [
            Shape {
              appearance USE CBOX_FRAME
              geometry DEF G_BOX_Frame1 Box {
                size 0.7 0.1 0.01
              }
            }
            Transform {
              translation 0 0.88 0
              children [
                Shape {
                  appearance USE CBOX_FRAME
                  geometry USE G_BOX_Frame1
                }
              ]
            }
          ]
        }
      ]
    }
    Group {
      children [
        Solid {
          translation 0 0.4 0
          rotation 0 0 1 0.71
          children [
            Shape {
              appearance USE CBOX_FRAME
              geometry Box {
                size 1.2 0.07 0.01
              }
            }
            Transform {
              rotation 0 0 1 1.7
              children [
                Shape {
                  appearance USE CBOX_FRAME
                  geometry Box {
                    size 1.2 0.07 0.01
                  }
                }
              ]
            }
          ]
          name "solid(1)"
        }
      ]
    }
  ]
  name "solid(4)"
}
DEF ELICE_FRAME Solid {
  translation 0 1.2 0
  children [
    Group {
      children [
        Shape {
          appearance DEF C_ELICE_FRAME PBRAppearance {
            baseColor 0.3058823529411765 0.6039215686274509 0.023529411764705882
            metalness 0
          }
          geometry DEF G_ELICE_CYL Cylinder {
            height 0.4
            radius 0.05
          }
        }
        HingeJoint {
          jointParameters HingeJointParameters {
            staticFriction 0.02
          }
          endPoint Solid {
            translation 0.08 0.25 0
            rotation 0 0 1 1.57
            children [
              Shape {
                appearance USE C_ELICE_FRAME
                geometry DEF G_HELICE_CYLINDER Cylinder {
                  height 0.4
                  radius 0.05
                }
              }
              HingeJoint {
                jointParameters HingeJointParameters {
                  staticFriction 0.01
                }
                endPoint Solid {
                  translation 0 -0.205 0
                  rotation 0 1 0 0.78
                  children [
                    Shape {
                      appearance USE C_ELICE_FRAME
                      geometry DEF G_HELICE_1 Box {
                        size 0.5 0.01 0.1
                      }
                    }
                    HingeJoint {
                      jointParameters HingeJointParameters {
                        staticFriction 0.01
                      }
                      endPoint Solid {
                        rotation 0 1 0 1.57
                        children [
                          Shape {
                            appearance USE C_ELICE_FRAME
                            geometry DEF G_HELICE_2 Box {
                              size 0.5 0.01 0.1
                            }
                          }
                        ]
                        boundingObject USE G_HELICE_2
                        physics Physics {
                        }
                      }
                    }
                  ]
                  boundingObject USE G_HELICE_1
                  physics Physics {
                  }
                  recognitionColors [
                    0.12549019607843137 0.2901960784313726 0.5294117647058824
                  ]
                }
              }
            ]
            boundingObject USE G_HELICE_CYLINDER
            physics Physics {
            }
          }
        }
      ]
    }
  ]
  name "solid(5)"
  boundingObject USE G_ELICE_CYL
}
